‚úì Model directory: ../../newModels
Using device: cuda

=== Model Directory Configuration ===
üìÅ Model directory: ../../newModels
üìÅ Directory exists: ‚úì

=== Expected Model Paths ===
üìç Main model: ../../newModels/bestmodel_main/best_model.pt
üìç Healer model: ../../newModels/bestmodel_healer/best_model.pt
üìç TTT3fc model: ../../newModels/bestmodel_ttt3fc/best_model.pt
üìç Blended3fc model: ../../newModels/bestmodel_blended3fc/best_model.pt

=== Checking for existing models (mode: all) ===

=== Training Main Classification Model ===
Using device: cuda
Phase 1: Finding an initial working batch size...
Starting batch size 128 fits in memory!
Phase 2: Refining batch size around 128...
Testing batch size: 144...
Testing batch size: 160...
Testing batch size: 152...
Testing batch size: 148...
Testing batch size: 146...
Testing batch size: 145...
Found optimal batch size: 144
Using safe batch size: 139
Training set size: 100000
Validation set size: 10000
Epoch 1/50: 100%|‚ñà‚ñà‚ñà‚ñà‚ñà‚ñà‚ñà‚ñà‚ñà‚ñà‚ñà‚ñà‚ñà‚ñà‚ñà‚ñà‚ñà‚ñà| 720/720 [02:44<00:00,  4.37it/s, loss=4.24]
Epoch 1/50 - Train Loss: 4.7902, Train Acc: 0.0599, Val Loss: 4.0844, Val Acc: 0.1342
Traceback (most recent call last):
  File "/home/david-lacour/Documents/transformerVision/githubs/VizInt/autoflex/autotinymodels/main_baselines_3fc.py", line 608, in <module>
    main()
  File "/home/david-lacour/Documents/transformerVision/githubs/VizInt/autoflex/autotinymodels/main_baselines_3fc.py", line 454, in main
    main_model = train_main_model(args.dataset, model_dir=args.model_dir)
                 ^^^^^^^^^^^^^^^^^^^^^^^^^^^^^^^^^^^^^^^^^^^^^^^^^^^^^^^^
  File "/home/david-lacour/Documents/transformerVision/githubs/VizInt/autoflex/autotinymodels/new_new.py", line 884, in train_main_model
    wandb.save(str(checkpoint_path))
  File "/home/david-lacour/.pyenv/versions/myenv/lib/python3.12/site-packages/wandb/sdk/wandb_run.py", line 406, in wrapper
    return func(self, *args, **kwargs)
           ^^^^^^^^^^^^^^^^^^^^^^^^^^^
  File "/home/david-lacour/.pyenv/versions/myenv/lib/python3.12/site-packages/wandb/sdk/wandb_run.py", line 464, in wrapper_fn
    return func(self, *args, **kwargs)
           ^^^^^^^^^^^^^^^^^^^^^^^^^^^
  File "/home/david-lacour/.pyenv/versions/myenv/lib/python3.12/site-packages/wandb/sdk/wandb_run.py", line 451, in wrapper
    return func(self, *args, **kwargs)
           ^^^^^^^^^^^^^^^^^^^^^^^^^^^
  File "/home/david-lacour/.pyenv/versions/myenv/lib/python3.12/site-packages/wandb/sdk/wandb_run.py", line 2175, in save
    return self._save(
           ^^^^^^^^^^^
  File "/home/david-lacour/.pyenv/versions/myenv/lib/python3.12/site-packages/wandb/sdk/wandb_run.py", line 2190, in _save
    raise ValueError("Glob may not walk above the base path")
ValueError: Glob may not walk above the base path
